<?xml version='1.0'?>

<robot name="mycar" xmlns:xacro="http://www.ros.org/wiki/xacro">

  <!-- 包含Gazebo插件的文件，用于模拟物理属性 -->
  <xacro:include filename="$(find car_nav2)/urdf/mycar.gazebo" />

  <!-- 包含RViz中的颜色定义文件，用于可视化配置 -->
  <xacro:include filename="$(find car_nav2)/urdf/materials.xacro" />

  <!-- 定义机器人底盘的参考点（base_footprint），用于标识机器人在平面上的位置 -->
  <link name="base_footprint"></link>

  <!-- 将base_footprint与base_link通过固定关节连接，base_link为机器人底盘的实际链接 -->
  <joint name="base_footprint_joint" type="fixed">
    <origin xyz="0 0 0" rpy="0 0 0" />
    <parent link="base_footprint"/>
    <child link="base_link" />
  </joint>

  <!-- 定义机器人底盘（base_link）的属性，包括惯性、碰撞模型和视觉模型 -->
  <link name='base_link'>
    <pose>0 0 0.1 0 0 0</pose>

    <!-- 定义惯性属性，用于物理模拟中的质量分布 -->
    <inertial>
      <mass value="15.0"/>
      <origin xyz="0.0 0 0" rpy=" 0 0 0"/>
      <inertia
          ixx="0.0625" ixy="0" ixz="0"
          iyy="0.2125" iyz="0"
          izz="0.25"
      />
    </inertial>

    <!-- 定义底盘的碰撞模型，用于物理引擎的碰撞检测 -->
    <collision name='collision'>
      <origin xyz="0 0 0" rpy=" 0 0 0"/>
      <geometry>
        <box size=".4 .2 .1"/>
      </geometry>
    </collision>

    <!-- 定义底盘的视觉模型，用于可视化展示 -->
    <visual name='base_link_visual'>
      <origin xyz="0 0 0" rpy=" 0 0 0"/>
      <geometry>
        <mesh filename="package://car_nav2/meshes/mycar.dae" />
      </geometry>
    </visual>

    <!-- 定义后轮支撑点的碰撞模型和视觉模型 -->
    <collision name='rear_caster_collision'>
      <origin xyz="-0.15 0 -0.05" rpy=" 0 0 0"/>
      <geometry>
        <sphere radius="0.0499"/>
      </geometry>
    </collision>

    <visual name='rear_caster_visual'>
      <origin xyz="-0.15 0 -0.05" rpy=" 0 0 0"/>
      <geometry>
        <sphere radius="0.05"/>
      </geometry>
    </visual>

    <!-- 定义前轮支撑点的碰撞模型和视觉模型 -->
    <collision name='front_caster_collision'>
      <origin xyz="0.15 0 -0.05" rpy=" 0 0 0"/>
      <geometry>
        <sphere radius="0.0499"/>
      </geometry>
    </collision>

    <visual name='front_caster_visual'>
      <origin xyz="0.15 0 -0.05" rpy=" 0 0 0"/>
      <geometry>
        <sphere radius="0.05"/>
      </geometry>
    </visual>

  </link>

  <!-- 定义左轮的关节和链接 -->
  <joint type="continuous" name="left_wheel_joint">
    <origin xyz="0 0.15 0" rpy="0 0 0"/>
    <child link="left_wheel"/>
    <parent link="base_link"/>
    <axis xyz="0 1 0" rpy="0 0 0"/>
    <limit effort="100" velocity="10"/>
    <dynamics damping="1.0" friction="1.0"/>
  </joint>

  <link name='left_wheel'>
    <!-- 定义左轮的惯性属性 -->
    <inertial>
      <mass value="5.0"/>
      <origin xyz="0 0 0" rpy="0 1.5707 1.5707"/>
      <inertia
          ixx="0.014" ixy="0" ixz="0"
          iyy="0.014" iyz="0"
          izz="0.025"
      />
    </inertial>

    <!-- 定义左轮的碰撞模型 -->
    <collision>
      <origin xyz="0 0 0" rpy="0 1.5707 1.5707"/>
      <geometry>
        <cylinder radius=".1" length=".05"/>
      </geometry>
    </collision>

    <!-- 定义左轮的视觉模型 -->
    <visual name='left_wheel_visual'>
      <origin xyz="0 0 0" rpy="0 1.5707 1.5707"/>
      <geometry>
        <mesh filename = "package://car_nav2/meshes/wheel.dae"/>
      </geometry>
    </visual>
  </link>

  <!-- 定义右轮的关节和链接 -->
  <joint type="continuous" name="right_wheel_joint">
    <origin xyz="0 -0.15 0" rpy="0 0 0"/>
    <child link="right_wheel"/>
    <parent link="base_link"/>
    <axis xyz="0 1 0" rpy="0 0 0"/>
    <limit effort="100" velocity="10"/>
    <dynamics damping="1.0" friction="1.0"/>
  </joint>

  <link name='right_wheel'>
    <!-- 定义右轮的惯性属性 -->
    <inertial>
      <mass value="5.0"/>
      <origin xyz="0 0 0" rpy="0 1.5707 1.5707"/>
      <inertia
          ixx="0.014" ixy="0" ixz="0"
          iyy="0.014" iyz="0"
          izz="0.025"
      />
    </inertial>

    <!-- 定义右轮的碰撞模型 -->
    <collision>
      <origin xyz="0 0 0" rpy="0 1.5707 1.5707"/>
      <geometry>
        <cylinder radius=".1" length=".05"/>
      </geometry>
    </collision>

    <!-- 定义右轮的视觉模型 -->
    <visual name='right_wheel_visual'>
      <origin xyz="0 0 0" rpy="0 1.5707 1.5707"/>
      <geometry>
        <mesh filename = "package://car_nav2/meshes/wheel.dae"/>
      </geometry>
    </visual>
  </link>

  <!-- 定义Gazebo物理参数，包括摩擦力和其他动态属性 -->
  <gazebo reference="left_wheel">
    <mu1>0.2</mu1>
    <mu2>0.2</mu2>
    <kp>1000000.0</kp>
    <kd>100.0</kd>
    <minDepth>0.0001</minDepth>
    <maxVel>1.0</maxVel>
  </gazebo>

  <gazebo reference="right_wheel">
    <mu1>0.2</mu1>
    <mu2>0.2</mu2>
    <kp>1000000.0</kp>
    <kd>100.0</kd>
    <minDepth>0.0001</minDepth>
    <maxVel>1.0</maxVel>
  </gazebo>

  <gazebo reference="base_link">
    <mu1>0.000002</mu1>
    <mu2>0.000002</mu2>
  </gazebo>

  <!-- 定义IMU传感器的固定关节 -->
  <joint name="imu_joint" type="fixed">
    <origin xyz="0 0 0" rpy="0 0 0" />
    <parent link="base_link"/>
    <child link="imu_link" />
  </joint>

  <link name="imu_link">
  </link>

  <!-- 定义激光雷达（Lidar）的固定关节和属性 -->
  <joint type="fixed" name="scan_joint">
    <origin xyz="0.0 0 0.15" rpy="0 0 0"/>
    <child link="scan_link"/>
    <parent link="base_link"/>
    <axis xyz="0 1 0" rpy="0 0 0"/>
  </joint>

  <link name='scan_link'>
    <!-- 定义激光雷达的惯性属性 -->
    <inertial>
      <mass value="1e-5"/>
      <origin xyz="0 0 0" rpy="0 0 0"/>
      <inertia
          ixx="1e-6" ixy="0" ixz="0"
          iyy="1e-6" iyz="0"
          izz="1e-6"
      />
    </inertial>

    <!-- 定义激光雷达的碰撞模型 -->
    <collision name='collision'>
      <origin xyz="0 0 0" rpy="0 0 0"/>
      <geometry>
        <box size=".1 .1 .1"/>
      </geometry>
    </collision>

    <!-- 定义激光雷达的视觉模型 -->
    <visual name='scan_link_visual'>
      <origin xyz="0 0 0" rpy="0 0 0"/>
      <geometry>
        <mesh filename = "package://car_nav2/meshes/lidar.dae"/>
      </geometry>
    </visual>

  </link>

  <!-- Gazebo中的激光雷达属性配置 -->
  <gazebo reference="scan_link">
    <selfCollide>false</selfCollide>
    <mu1 value="0.05" />
    <mu2 value="0.05" />
  </gazebo>

</robot>
